Workbook

Sheet ReadMe
A1: Conference research, window 2026-09-28 to 2026-12-31
A3: Input
A4: As-of date (edit me) | B4: 46315 | C4: Hardcoded: today's date as given in this session (2026-10-20). Drives the Status column and Summary. Type a new date, or enter =TODAY() to make Status live.
A5: Source data retrieved | B5: 46293 | C5: Every source in SourceMap was retrieved on this date via web-search results. Nothing was re-checked when this workbook was built.
A6: Days since retrieval | B6: =B4-B5 -> 22 | C6: Calculated: as-of date minus retrieval date. Dates, venues and newly announced events may have changed since retrieval.
A8: READ THIS FIRST
A9: 1. No organizer page was opened. The network proxy blocked all four of your example sites (MeetMax, Lytham Partners, NIBA, The PIPEs Conference) and most organizer sites. Dates come from web-search result text and press releases.
A10: 2. Confidence: Confirmed = dates and location stated in at least one retrieved source. Partial = a field is missing, single-source, or sources conflict. Unverified items are only on the Leads sheet and carry no dates to rely on.
A11: 3. Status (Conferences sheet) is a calculation from Start/End dates and the as-of date. It adds no new facts. Rows whose dates are conflicted or not exact show 'Check dates'.
A12: 4. Coverage is incomplete: the search budget ran out before many banks and sectors were searched (see Audit sheet). Absence from this list means 'not found', not 'does not exist'.
A13: 5. MeetMax event_145007 (your first example) could not be identified. See Leads sheet.
A14: 6. Scope assumption: your four examples were read as micro/small-cap investor, PIPE and capital-markets events. Tier B (bank-hosted/sector) and Tier C (adjacent) are broader; filter them out if they are noise.
A15: Colors: blue on yellow = input you can change. Green = value pulled from another sheet. Black = static data or formula.
A16: Sheets: Conferences (all 60 dated events) | Summary (counts, formulas) | Leads (unverified, no dates to rely on) | SourceMap (IDs and URLs) | Audit (what to fix or check before shipping; coverage gaps).

Sheet Conferences
A1: # | B1: Tier | C1: Conference | D1: Organizer | E1: Start date | F1: End date | G1: Dates as reported | H1: Location / format | I1: Focus / audience | J1: Src IDs | K1: Confidence | L1: Flags / discrepancies | M1: Status | N1: Days to start | O1: First source URL
A2: 1 | B2: A. Micro/small-cap & capital raising | C2: Annual Smallcap Discoveries Conference | D2: Small Cap Discoveries | E2: 46293 | F2: 46294 | G2: Sep 28-29, 2026 | H2: JW Marriott Parq, Vancouver BC; in person | I2: Small-cap issuers; investors, 1x1s | J2: S3,S4 | K2: Confirmed | L2: Starts today (window start). | M2: =IF(E2="","Check dates",IF(ReadMe!$B$4<E2,"Upcoming",IF(ReadMe!$B$4<=IF(F2="",E2,F2),"In progress / today","Past"))) -> Past | N2: =IF(E2="","",E2-ReadMe!$B$4) -> -22 | O2: =IFERROR(INDEX(SourceMap!$C$2:$C$73,MATCH(LEFT(J2,FIND(",",J2&",")-1),SourceMap!$A$2:$A$73,0)),"") -> https://smallcapdiscoveries.com/annual-smallcap-discoveries-conference-2026/
A3: 2 | B3: C. Adjacent (dealmaking, family office, PE/credit) | C3: SuperReturn Asia 2026 | D3: Informa Connect | E3: 46293 | F3: 46296 | G3: Sep 28-Oct 1, 2026 | H3: Marina Bay Sands, Singapore | I3: Private markets, PE, private credit | J3: S60 | K3: Partial | L3: Search summary only. | M3: =IF(E3="","Check dates",IF(ReadMe!$B$4<E3,"Upcoming",IF(ReadMe!$B$4<=IF(F3="",E3,F3),"In progress / today","Past"))) -> Past | N3: =IF(E3="","",E3-ReadMe!$B$4) -> -22 | O3: =IFERROR(INDEX(SourceMap!$C$2:$C$73,MATCH(LEFT(J3,FIND(",",J3&",")-1),SourceMap!$A$2:$A$73,0)),"") -> https://informaconnect.com/superreturnasia/ | https://informaconnect.com/superreturn-north-america/ | https://ilpa.org/industry-event/superreturn-middle-east/ | https://10times.com/superreturn-middle-east
A4: 3 | B4: A. Micro/small-cap & capital raising | C4: Lytham Partners Fall 2026 Investor Conference | D4: Lytham Partners | E4: 46294 | F4: 46295 | G4: Sep 29-30, 2026 | H4: Virtual (webcast + virtual 1x1s) | I4: Micro/small-cap issuers; institutional investors | J4: S1,S2,S67 | K4: Confirmed | L4: Your example. Official page blocked, dates from issuer releases. | M4: =IF(E4="","Check dates",IF(ReadMe!$B$4<E4,"Upcoming",IF(ReadMe!$B$4<=IF(F4="",E4,F4),"In progress / today","Past"))) -> Past | N4: =IF(E4="","",E4-ReadMe!$B$4) -> -21 | O4: =IFERROR(INDEX(SourceMap!$C$2:$C$73,MATCH(LEFT(J4,FIND(",",J4&",")-1),SourceMap!$A$2:$A$73,0)),"") -> https://www.globenewswire.com/news-release/2026/09/28/3369705/0/en/comstock-to-participate-in-the-lytham-partners-fall-2026-investor-conference.html
A5: 4 | B5: B. Bank-hosted & sector investor conf. | C5: ROTH 5th Annual Healthcare Opportunities Conference | D5: ROTH Capital Partners | E5: 46294 | F5: 46294 | G5: Sep 29, 2026 | H5: Metropolitan Club, New York; in person, invitation-only | I5: Healthcare | J5: S5 | K5: Confirmed | L5: Welcome reception + KOL dinner Sep 28. | M5: =IF(E5="","Check dates",IF(ReadMe!$B$4<E5,"Upcoming",IF(ReadMe!$B$4<=IF(F5="",E5,F5),"In progress / today","Past"))) -> Past | N5: =IF(E5="","",E5-ReadMe!$B$4) -> -21 | O5: =IFERROR(INDEX(SourceMap!$C$2:$C$73,MATCH(LEFT(J5,FIND(",",J5&",")-1),SourceMap!$A$2:$A$73,0)),"") -> https://www.globenewswire.com/news-release/2026/09/22/3366425/0/en/roth-to-host-5th-annual-healthcare-opportunities-conference-on-september-29-in-new-york-city.html
A6: 5 | B6: B. Bank-hosted & sector investor conf. | C6: Stifel Virtual Cardiometabolic Forum | D6: Stifel | E6: 46295 | F6: 46295 | G6: Sep 30, 2026 | H6: Virtual | I6: Cardiometabolic biotech | J6: S62 | K6: Partial | L6: Single source (issuer release). | M6: =IF(E6="","Check dates",IF(ReadMe!$B$4<E6,"Upcoming",IF(ReadMe!$B$4<=IF(F6="",E6,F6),"In progress / today","Past"))) -> Past | N6: =IF(E6="","",E6-ReadMe!$B$4) -> -20 | O6: =IFERROR(INDEX(SourceMap!$C$2:$C$73,MATCH(LEFT(J6,FIND(",",J6&",")-1),SourceMap!$A$2:$A$73,0)),"") -> https://www.globenewswire.com/news-release/2026/09/25/3369327/0/en/bioage-labs-to-present-at-upcoming-investor-conferences.html
A7: 6 | B7: A. Micro/small-cap & capital raising | C7: AI & Tech Virtual Investor Conference | D7: Virtual Investor Conferences (OTC Markets Group); B2i Digital marketing | E7: 46296 | F7: 46296 | G7: Oct 1, 2026 | H7: Virtual | I7: AI / technology public companies | J7: S8,S9 | K7: Confirmed | M7: =IF(E7="","Check dates",IF(ReadMe!$B$4<E7,"Upcoming",IF(ReadMe!$B$4<=IF(F7="",E7,F7),"In progress / today","Past"))) -> Past | N7: =IF(E7="","",E7-ReadMe!$B$4) -> -19 | O7: =IFERROR(INDEX(SourceMap!$C$2:$C$73,MATCH(LEFT(J7,FIND(",",J7&",")-1),SourceMap!$A$2:$A$73,0)),"") -> https://www.globenewswire.com/news-release/2026/09/28/3369959/0/en/ai-tech-virtual-investor-conference-agenda-announced.html
A8: 7 | B8: A. Micro/small-cap & capital raising | C8: Noble Capital Markets Oct 2026 Emerging Growth Virtual Equity Conference | D8: Noble Capital Markets | E8: 46296 | F8: 46297 | G8: Oct 1-2, 2026 | H8: Virtual; presentations, 1x1s | I8: Small / micro / middle-market issuers | J8: S10,S11,S14 | K8: Confirmed | M8: =IF(E8="","Check dates",IF(ReadMe!$B$4<E8,"Upcoming",IF(ReadMe!$B$4<=IF(F8="",E8,F8),"In progress / today","Past"))) -> Past | N8: =IF(E8="","",E8-ReadMe!$B$4) -> -19 | O8: =IFERROR(INDEX(SourceMap!$C$2:$C$73,MATCH(LEFT(J8,FIND(",",J8&",")-1),SourceMap!$A$2:$A$73,0)),"") -> https://nobleconference.com/virtual-october-2026/
A9: 8 | B9: A. Micro/small-cap & capital raising | C9: The Small Cap Showcase (NYC) | D9: Not verified | E9: 46296 | F9: 46296 | G9: Oct 1, 2026 | H9: New York City; venue NOT VERIFIED; in person | I9: ~25 small caps; family offices, institutions | J9: S7 | K9: Partial | L9: Year inferred from 'Thursday, Oct 1' + registration cutoff text; Oct 1, 2026 is a Thursday (checked). Single source. | M9: =IF(E9="","Check dates",IF(ReadMe!$B$4<E9,"Upcoming",IF(ReadMe!$B$4<=IF(F9="",E9,F9),"In progress / today","Past"))) -> Past | N9: =IF(E9="","",E9-ReadMe!$B$4) -> -19 | O9: =IFERROR(INDEX(SourceMap!$C$2:$C$73,MATCH(LEFT(J9,FIND(",",J9&",")-1),SourceMap!$A$2:$A$73,0)),"") -> https://www.smallcapshowcase.com/
A10: 9 | B10: B. Bank-hosted & sector investor conf. | C10: ROTH Critical Mass in Emerging Nuclear Technology (inaugural) | D10: ROTH Capital Partners | E10: 46296 | F10: 46296 | G10: Oct 1, 2026 | H10: New York; venue/format NOT VERIFIED | I10: Nuclear technology | J10: S6 | K10: Partial | M10: =IF(E10="","Check dates",IF(ReadMe!$B$4<E10,"Upcoming",IF(ReadMe!$B$4<=IF(F10="",E10,F10),"In progress / today","Past"))) -> Past | N10: =IF(E10="","",E10-ReadMe!$B$4) -> -19 | O10: =IFERROR(INDEX(SourceMap!$C$2:$C$73,MATCH(LEFT(J10,FIND(",",J10&",")-1),SourceMap!$A$2:$A$73,0)),"") -> https://www.investorwire.com/investor-news-breaks/investornewsbreaks-roth-capital-partners-hosts-and-sponsors-investor-events-through-june-2027/
A11: 10 | B11: A. Micro/small-cap & capital raising | C11: NIBA 153rd Investment Conference | D11: National Investment Banking Association | E11: 46301 | F11: 46302 | G11: Oct 6-7, 2026 | H11: Westin Fort Lauderdale Beach Resort, FL; in person | I11: ~30 emerging-growth cos.; 350+ investment professionals (organizer claim) | J11: S12,S13,S14 | K11: Confirmed | L11: Your example. | M11: =IF(E11="","Check dates",IF(ReadMe!$B$4<E11,"Upcoming",IF(ReadMe!$B$4<=IF(F11="",E11,F11),"In progress / today","Past"))) -> Past | N11: =IF(E11="","",E11-ReadMe!$B$4) -> -14 | O11: =IFERROR(INDEX(SourceMap!$C$2:$C$73,MATCH(LEFT(J11,FIND(",",J11&",")-1),SourceMap!$A$2:$A$73,0)),"") -> https://nibanet.org/conference/niba-october-6-7-2026-ft-lauderdale-fl-conference/
A12: 11 | B12: C. Adjacent (dealmaking, family office, PE/credit) | C12: ACG Midwest Capital Connection | D12: ACG Chicago | E12: 46302 | F12: 46303 | G12: Oct 7-8, 2026 | H12: Navy Pier, Chicago | I12: Middle-market dealmaking | J12: S42 | K12: Confirmed | M12: =IF(E12="","Check dates",IF(ReadMe!$B$4<E12,"Upcoming",IF(ReadMe!$B$4<=IF(F12="",E12,F12),"In progress / today","Past"))) -> Past | N12: =IF(E12="","",E12-ReadMe!$B$4) -> -13 | O12: =IFERROR(INDEX(SourceMap!$C$2:$C$73,MATCH(LEFT(J12,FIND(",",J12&",")-1),SourceMap!$A$2:$A$73,0)),"") -> https://www.acg.org/chicago/events/2026-midwest-capital-connection
A13: 12 | B13: A. Micro/small-cap & capital raising | C13: Maxim Growth Summit 2026 | D13: Maxim Group | E13: 46307 | F13: 46309 | G13: Oct 12-14, 2026 | H13: Hard Rock Hotel, New York; in person, invitation-only | I13: Growth issuers; institutional investors | J13: S15,S16 | K13: Confirmed | L13: DISCREPANCY: organizer page Oct 12-14; SBC Medical release lists only Oct 14 (its presentation day; likely not a conflict). | M13: =IF(E13="","Check dates",IF(ReadMe!$B$4<E13,"Upcoming",IF(ReadMe!$B$4<=IF(F13="",E13,F13),"In progress / today","Past"))) -> Past | N13: =IF(E13="","",E13-ReadMe!$B$4) -> -8 | O13: =IFERROR(INDEX(SourceMap!$C$2:$C$73,MATCH(LEFT(J13,FIND(",",J13&",")-1),SourceMap!$A$2:$A$73,0)),"") -> https://maximgrp.com/2026-growth-summit
A14: 13 | B14: C. Adjacent (dealmaking, family office, PE/credit) | C14: Sohn San Francisco Investment Conference | D14: Sohn Conference Foundation | E14: 46308 | F14: 46308 | G14: Oct 13, 2026 | H14: Hyatt Regency San Francisco | I14: Investment ideas (hedge/long-only) | J14: S58 | K14: Confirmed | M14: =IF(E14="","Check dates",IF(ReadMe!$B$4<E14,"Upcoming",IF(ReadMe!$B$4<=IF(F14="",E14,F14),"In progress / today","Past"))) -> Past | N14: =IF(E14="","",E14-ReadMe!$B$4) -> -7 | O14: =IFERROR(INDEX(SourceMap!$C$2:$C$73,MATCH(LEFT(J14,FIND(",",J14&",")-1),SourceMap!$A$2:$A$73,0)),"") -> https://www.sohnconference.org/san-francisco
A15: 14 | B15: C. Adjacent (dealmaking, family office, PE/credit) | C15: ACG Aerospace & Defense Middle Market Leadership Forum | D15: ACG Global | E15: 46309 | F15: 46310 | G15: Oct 14-15, 2026 | H15: Marina del Rey Marriott, CA | I15: A&D dealmakers | J15: S43 | K15: Confirmed | L15: Sector-specific. | M15: =IF(E15="","Check dates",IF(ReadMe!$B$4<E15,"Upcoming",IF(ReadMe!$B$4<=IF(F15="",E15,F15),"In progress / today","Past"))) -> Past | N15: =IF(E15="","",E15-ReadMe!$B$4) -> -6 | O15: =IFERROR(INDEX(SourceMap!$C$2:$C$73,MATCH(LEFT(J15,FIND(",",J15&",")-1),SourceMap!$A$2:$A$73,0)),"") -> https://www.acg.org/events/2026-acg-aerospace-defense-middle-market-leadership-forum
A16: 15 | B16: A. Micro/small-cap & capital raising | C16: The ThinkEquity Conference 2026 | D16: ThinkEquity | E16: 46310 | F16: 46310 | G16: Oct 15, 2026 | H16: New York; in person | I16: Emerging growth; issuers, investors, bankers | J16: S17,S14,S18 | K16: Confirmed | L16: Date confirmed (KOIL release: Thursday Oct 15; weekday checked). VENUE CONFLICT: Mandarin Oriental (10times) vs Renaissance Times Square (a Marriott page). | M16: =IF(E16="","Check dates",IF(ReadMe!$B$4<E16,"Upcoming",IF(ReadMe!$B$4<=IF(F16="",E16,F16),"In progress / today","Past"))) -> Past | N16: =IF(E16="","",E16-ReadMe!$B$4) -> -5 | O16: =IFERROR(INDEX(SourceMap!$C$2:$C$73,MATCH(LEFT(J16,FIND(",",J16&",")-1),SourceMap!$A$2:$A$73,0)),"") -> https://www.loeb.com/en/newsevents/events/2026/10/thinkequity-conference
A17: 16 | B17: A. Micro/small-cap & capital raising | C17: LD Micro 20th Annual Main Event | D17: LD Micro | E17: 46314 | F17: 46316 | G17: Oct 19-21, 2026 | H17: Luxe Sunset Blvd Hotel, Los Angeles; in person | I17: Micro/small-cap issuers and investors | J17: S19 | K17: Confirmed | L17: Single source (search-result title). Site blocked. | M17: =IF(E17="","Check dates",IF(ReadMe!$B$4<E17,"Upcoming",IF(ReadMe!$B$4<=IF(F17="",E17,F17),"In progress / today","Past"))) -> In progress / today | N17: =IF(E17="","",E17-ReadMe!$B$4) -> -1 | O17: =IFERROR(INDEX(SourceMap!$C$2:$C$73,MATCH(LEFT(J17,FIND(",",J17&",")-1),SourceMap!$A$2:$A$73,0)),"") -> https://ldmicroevents.com/
A18: 17 | B18: A. Micro/small-cap & capital raising | C18: CfPA 2026 Regulated Investment Crowdfunding Summit | D18: CfPA (full name not verified) | E18: 46315 | F18: 46316 | G18: Oct 20-21, 2026 | H18: National Union Building, 918 F St NW, Washington DC; in person | I18: Reg CF / Reg A / crowdfunding advocacy | J18: S41 | K18: Confirmed | L18: Oct 20 = advocacy visits + reception; Oct 21 = summit day. | M18: =IF(E18="","Check dates",IF(ReadMe!$B$4<E18,"Upcoming",IF(ReadMe!$B$4<=IF(F18="",E18,F18),"In progress / today","Past"))) -> In progress / today | N18: =IF(E18="","",E18-ReadMe!$B$4) -> 0 | O18: =IFERROR(INDEX(SourceMap!$C$2:$C$73,MATCH(LEFT(J18,FIND(",",J18&",")-1),SourceMap!$A$2:$A$73,0)),"") -> https://www.crowdfundingecosystem.com/2026-cfpa-regulated-investment-crowdfunding-summit
A19: 18 | B19: C. Adjacent (dealmaking, family office, PE/credit) | C19: Family Office & Private Wealth Management Forum West | D19: Opal Group | E19: 46316 | F19: 46318 | G19: Oct 21-23, 2026 | H19: Napa Valley Marriott, CA | I19: Family offices | J19: S46 | K19: Confirmed | M19: =IF(E19="","Check dates",IF(ReadMe!$B$4<E19,"Upcoming",IF(ReadMe!$B$4<=IF(F19="",E19,F19),"In progress / today","Past"))) -> Upcoming | N19: =IF(E19="","",E19-ReadMe!$B$4) -> 1 | O19: =IFERROR(INDEX(SourceMap!$C$2:$C$73,MATCH(LEFT(J19,FIND(",",J19&",")-1),SourceMap!$A$2:$A$73,0)),"") -> https://opalgroup.net/finance/family-office-private-wealth-management-forum-west-2026/
A20: 19 | B20: A. Micro/small-cap & capital raising | C20: Planet MicroCap Showcase: Toronto 2026 | D20: Planet MicroCap Holdings LLC | E20: 46322 | F20: 46324 | G20: Oct 27-29, 2026 | H20: Arcadian Loft (Arcadian Court & Loft), Toronto; in person | I20: Microcap issuers/investors; Day 3 = 1x1s | J20: S20,S14 | K20: Confirmed | L20: Free for verified investors per event page summary. | M20: =IF(E20="","Check dates",IF(ReadMe!$B$4<E20,"Upcoming",IF(ReadMe!$B$4<=IF(F20="",E20,F20),"In progress / today","Past"))) -> Upcoming | N20: =IF(E20="","",E20-ReadMe!$B$4) -> 7 | O20: =IFERROR(INDEX(SourceMap!$C$2:$C$73,MATCH(LEFT(J20,FIND(",",J20&",")-1),SourceMap!$A$2:$A$73,0)),"") -> https://planetmicrocap.com/register-today-planet-microcap-toronto-2026/
A21: 20 | B21: C. Adjacent (dealmaking, family office, PE/credit) | C21: ACG NY DealMaker Series, Fall Edition | D21: ACG New York | E21: 46322 | F21: 46322 | G21: Oct 27, 2026 | H21: New York Athletic Club, NYC (evening) | I21: Middle-market dealmakers | J21: S45 | K21: Partial | L21: Individual event URL not captured. | M21: =IF(E21="","Check dates",IF(ReadMe!$B$4<E21,"Upcoming",IF(ReadMe!$B$4<=IF(F21="",E21,F21),"In progress / today","Past"))) -> Upcoming | N21: =IF(E21="","",E21-ReadMe!$B$4) -> 7 | O21: =IFERROR(INDEX(SourceMap!$C$2:$C$73,MATCH(LEFT(J21,FIND(",",J21&",")-1),SourceMap!$A$2:$A$73,0)),"") -> https://www.acg.org/nyc/events
A22: 21 | B22: A. Micro/small-cap & capital raising | C22: Emerging Growth Conference 97 | D22: EmergingGrowth.com | E22: 46323 | F22: 46324 | G22: Oct 28-29, 2026 | H22: Format: virtual per two agents' summaries; not independently verified | I22: Small / micro-cap public issuers | J22: S21 | K22: Partial | L22: Dates from search summary only; prior editions were livestreamed. | M22: =IF(E22="","Check dates",IF(ReadMe!$B$4<E22,"Upcoming",IF(ReadMe!$B$4<=IF(F22="",E22,F22),"In progress / today","Past"))) -> Upcoming | N22: =IF(E22="","",E22-ReadMe!$B$4) -> 8 | O22: =IFERROR(INDEX(SourceMap!$C$2:$C$73,MATCH(LEFT(J22,FIND(",",J22&",")-1),SourceMap!$A$2:$A$73,0)),"") -> https://emerginggrowth.com/allconferences/ | https://emerginggrowth.com/conference/
A23: 22 | B23: B. Bank-hosted & sector investor conf. | C23: Red Cloud Fall Mining Showcase 2026 | D23: Red Cloud Financial Services | E23: 46323 | F23: 46324 | G23: Oct 28-29, 2026 | H23: Omni King Edward Hotel, Toronto; in person | I23: Mining / juniors | J23: S27 | K23: Confirmed | M23: =IF(E23="","Check dates",IF(ReadMe!$B$4<E23,"Upcoming",IF(ReadMe!$B$4<=IF(F23="",E23,F23),"In progress / today","Past"))) -> Upcoming | N23: =IF(E23="","",E23-ReadMe!$B$4) -> 8 | O23: =IFERROR(INDEX(SourceMap!$C$2:$C$73,MATCH(LEFT(J23,FIND(",",J23&",")-1),SourceMap!$A$2:$A$73,0)),"") -> https://redcloudfs.com/fallminingshowcase2026/ | https://thecse.com/event/red-cloud-fall-mining-showcase-2026/
A24: 23 | B24: B. Bank-hosted & sector investor conf. | C24: 52nd New Orleans Investment Conference | D24: Organizer NOT VERIFIED | E24: 46323 | F24: 46326 | G24: Oct 28-31, 2026 | H24: Hilton New Orleans Riverside; in person | I24: Macro / precious metals; mainly private investors | J24: S28 | K24: Confirmed | L24: Peripheral: not bank-hosted. | M24: =IF(E24="","Check dates",IF(ReadMe!$B$4<E24,"Upcoming",IF(ReadMe!$B$4<=IF(F24="",E24,F24),"In progress / today","Past"))) -> Upcoming | N24: =IF(E24="","",E24-ReadMe!$B$4) -> 8 | O24: =IFERROR(INDEX(SourceMap!$C$2:$C$73,MATCH(LEFT(J24,FIND(",",J24&",")-1),SourceMap!$A$2:$A$73,0)),"") -> https://www.eventbrite.com/e/2026-new-orleans-investment-conference-tickets-1765590632109 | https://www.bnnbloomberg.ca/investment-trends/2026/09/08/new-orleans-investment-conference-2026-a-sold-out-floor-a-marquee-roster-and-a-metals-market-on-the-rise/
A25: 24 | B25: B. Bank-hosted & sector investor conf. | C25: Central Canada Mineral Exploration Convention (CCMEC) | D25: Not verified | E25: 46328 | F25: 46329 | G25: Nov 2-3, 2026 | H25: Winnipeg, Manitoba; venue NOT VERIFIED | I25: Mineral exploration | J25: S29 | K25: Partial | L25: Peripheral; single source (issuer release). | M25: =IF(E25="","Check dates",IF(ReadMe!$B$4<E25,"Upcoming",IF(ReadMe!$B$4<=IF(F25="",E25,F25),"In progress / today","Past"))) -> Upcoming | N25: =IF(E25="","",E25-ReadMe!$B$4) -> 13 | O25: =IFERROR(INDEX(SourceMap!$C$2:$C$73,MATCH(LEFT(J25,FIND(",",J25&",")-1),SourceMap!$A$2:$A$73,0)),"") -> https://www.financialcontent.com/article/accwirecq-2026-9-28-grid-metals-to-participate-in-upcoming-investor-conferences
A26: 25 | B26: C. Adjacent (dealmaking, family office, PE/credit) | C26: CAASA Annual Conference 2026 | D26: CAASA | E26: 46329 | F26: 46330 | G26: Nov 3-4, 2026 | H26: Hotel Omni Mont-Royal, Montreal | I26: Pensions, family offices, alternatives | J26: S47 | K26: Confirmed | M26: =IF(E26="","Check dates",IF(ReadMe!$B$4<E26,"Upcoming",IF(ReadMe!$B$4<=IF(F26="",E26,F26),"In progress / today","Past"))) -> Upcoming | N26: =IF(E26="","",E26-ReadMe!$B$4) -> 14 | O26: =IFERROR(INDEX(SourceMap!$C$2:$C$73,MATCH(LEFT(J26,FIND(",",J26&",")-1),SourceMap!$A$2:$A$73,0)),"") -> https://caasa.ca/archives/events/caasa-annual-conference-2026
A27: 26 | B27: C. Adjacent (dealmaking, family office, PE/credit) | C27: ILPA Summit 2026 | D27: ILPA | E27: 46329 | F27: 46331 | G27: Nov 3-5, 2026 | H27: InterContinental New York Barclay | I27: LPs / GPs; emerging managers | J27: S51 | K27: Confirmed | M27: =IF(E27="","Check dates",IF(ReadMe!$B$4<E27,"Upcoming",IF(ReadMe!$B$4<=IF(F27="",E27,F27),"In progress / today","Past"))) -> Upcoming | N27: =IF(E27="","",E27-ReadMe!$B$4) -> 14 | O27: =IFERROR(INDEX(SourceMap!$C$2:$C$73,MATCH(LEFT(J27,FIND(",",J27&",")-1),SourceMap!$A$2:$A$73,0)),"") -> https://ilpa.org/conference/ilpa-summit/
A28: 27 | B28: A. Micro/small-cap & capital raising | C28: The PIPEs Conference | D28: DealFlow Events | E28: 46330 | F28: 46331 | G28: Nov 4-5, 2026 | H28: Seminole Hard Rock Hotel & Casino, Hollywood FL; in person | I28: PIPEs investors, issuers, bankers, lawyers | J28: S22,S23 | K28: Confirmed | L28: Your example. One AllEvents listing showed Nov 13-14 (appears stale; unresolved). | M28: =IF(E28="","Check dates",IF(ReadMe!$B$4<E28,"Upcoming",IF(ReadMe!$B$4<=IF(F28="",E28,F28),"In progress / today","Past"))) -> Upcoming | N28: =IF(E28="","",E28-ReadMe!$B$4) -> 15 | O28: =IFERROR(INDEX(SourceMap!$C$2:$C$73,MATCH(LEFT(J28,FIND(",",J28&",")-1),SourceMap!$A$2:$A$73,0)),"") -> https://www.morningstar.com/news/accesswire/1178554msn/the-pipes-conference-returns-to-the-hard-rock-hotel-casino-in-hollywood-fla-nov-4-5
A29: 28 | B29: B. Bank-hosted & sector investor conf. | C29: TAKESTOCK Calgary Investor Forum | D29: Not verified | E29: 46330 | F29: 46330 | G29: Nov 4, 2026 | H29: Calgary, Alberta; venue NOT VERIFIED | I29: Resource / small-cap | J29: S29 | K29: Partial | L29: Single source (issuer release). | M29: =IF(E29="","Check dates",IF(ReadMe!$B$4<E29,"Upcoming",IF(ReadMe!$B$4<=IF(F29="",E29,F29),"In progress / today","Past"))) -> Upcoming | N29: =IF(E29="","",E29-ReadMe!$B$4) -> 15 | O29: =IFERROR(INDEX(SourceMap!$C$2:$C$73,MATCH(LEFT(J29,FIND(",",J29&",")-1),SourceMap!$A$2:$A$73,0)),"") -> https://www.financialcontent.com/article/accwirecq-2026-9-28-grid-metals-to-participate-in-upcoming-investor-conferences
A30: 29 | B30: C. Adjacent (dealmaking, family office, PE/credit) | C30: PERE America Forum 2026 | D30: PEI | E30: 46330 | F30: 46331 | G30: Nov 4-5, 2026 | H30: Convene, 360 Madison Ave, NYC | I30: Private real estate | J30: S52 | K30: Confirmed | L30: Real-estate specific. | M30: =IF(E30="","Check dates",IF(ReadMe!$B$4<E30,"Upcoming",IF(ReadMe!$B$4<=IF(F30="",E30,F30),"In progress / today","Past"))) -> Upcoming | N30: =IF(E30="","",E30-ReadMe!$B$4) -> 15 | O30: =IFERROR(INDEX(SourceMap!$C$2:$C$73,MATCH(LEFT(J30,FIND(",",J30&",")-1),SourceMap!$A$2:$A$73,0)),"") -> https://live.peievents.com/private-real-estate/america
A31: 30 | B31: B. Bank-hosted & sector investor conf. | C31: Gold Advisor Network Summit | D31: Metals Investor Forum | E31: 46331 | F31: 46331 | G31: Nov 5, 2026 | H31: Fairmont Pacific Rim, Vancouver; in person | I31: Precious-metals juniors | J31: S30 | K31: Confirmed | M31: =IF(E31="","Check dates",IF(ReadMe!$B$4<E31,"Upcoming",IF(ReadMe!$B$4<=IF(F31="",E31,F31),"In progress / today","Past"))) -> Upcoming | N31: =IF(E31="","",E31-ReadMe!$B$4) -> 16 | O31: =IFERROR(INDEX(SourceMap!$C$2:$C$73,MATCH(LEFT(J31,FIND(",",J31&",")-1),SourceMap!$A$2:$A$73,0)),"") -> https://metalsinvestorforum.com/gold-advisor-network-summit/
A32: 31 | B32: C. Adjacent (dealmaking, family office, PE/credit) | C32: Pennsylvania Institutional Forum (12th) | D32: Markets Group | E32: 46331 | F32: 46331 | G32: Nov 5, 2026 | H32: Ritz-Carlton, Philadelphia | I32: Pensions / institutional LPs | J32: S53 | K32: Confirmed | L32: Closed-door. | M32: =IF(E32="","Check dates",IF(ReadMe!$B$4<E32,"Upcoming",IF(ReadMe!$B$4<=IF(F32="",E32,F32),"In progress / today","Past"))) -> Upcoming | N32: =IF(E32="","",E32-ReadMe!$B$4) -> 16 | O32: =IFERROR(INDEX(SourceMap!$C$2:$C$73,MATCH(LEFT(J32,FIND(",",J32&",")-1),SourceMap!$A$2:$A$73,0)),"") -> https://www.marketsgroup.org/forums/pennsylvania-institutional-forum
A33: 32 | B33: B. Bank-hosted & sector investor conf. | C33: UBS Global Healthcare Conference | D33: UBS | E33: 46334 | F33: 46337 | G33: Nov 8-11, 2026 | H33: PGA National Resort, Palm Beach Gardens FL; in person | I33: Healthcare | J33: S31 | K33: Confirmed | L33: Nov 8 = welcome/golf; sessions follow. | M33: =IF(E33="","Check dates",IF(ReadMe!$B$4<E33,"Upcoming",IF(ReadMe!$B$4<=IF(F33="",E33,F33),"In progress / today","Past"))) -> Upcoming | N33: =IF(E33="","",E33-ReadMe!$B$4) -> 19 | O33: =IFERROR(INDEX(SourceMap!$C$2:$C$73,MATCH(LEFT(J33,FIND(",",J33&",")-1),SourceMap!$A$2:$A$73,0)),"") -> https://www.ubs.com/global/en/investment-bank/ib-conferences/americas/global-healthcare-conference/overview.html
A34: 33 | B34: B. Bank-hosted & sector investor conf. | C34: Guggenheim 3rd Annual Healthcare Innovation Conference | D34: Guggenheim Securities | E34: 46335 | F34: 46337 | G34: Nov 9-11, 2026 | H34: Boston MA; venue NOT VERIFIED; in person | I34: Healthcare / biotech | J34: S32 | K34: Confirmed | L34: Issuer pages show Nov 9 and Nov 10 sessions. | M34: =IF(E34="","Check dates",IF(ReadMe!$B$4<E34,"Upcoming",IF(ReadMe!$B$4<=IF(F34="",E34,F34),"In progress / today","Past"))) -> Upcoming | N34: =IF(E34="","",E34-ReadMe!$B$4) -> 20 | O34: =IFERROR(INDEX(SourceMap!$C$2:$C$73,MATCH(LEFT(J34,FIND(",",J34&",")-1),SourceMap!$A$2:$A$73,0)),"") -> https://ir.moonlaketx.com/events/event-details/3rd-annual-guggenheim-healthcare-innovation-conference | https://investors.enterabio.com/events/event-details/guggenheim-securities-3rd-annual-healthcare-innovation-conference
A35: 34 | B35: B. Bank-hosted & sector investor conf. | C35: Precious Metals Summit Zurich 2026 | D35: Not verified | E35: 46335 | F35: 46337 | G35: Nov 9-11, 2026 | H35: Park Hyatt Zurich; in person, invitation-only | I35: Precious-metals issuers | J35: S33 | K35: Confirmed | M35: =IF(E35="","Check dates",IF(ReadMe!$B$4<E35,"Upcoming",IF(ReadMe!$B$4<=IF(F35="",E35,F35),"In progress / today","Past"))) -> Upcoming | N35: =IF(E35="","",E35-ReadMe!$B$4) -> 20 | O35: =IFERROR(INDEX(SourceMap!$C$2:$C$73,MATCH(LEFT(J35,FIND(",",J35&",")-1),SourceMap!$A$2:$A$73,0)),"") -> https://www.precioussummit.com/events/2026-precious-metals-summit-zurich/
A36: 35 | B36: C. Adjacent (dealmaking, family office, PE/credit) | C36: ACG NY Middle Market Week 2026 | D36: ACG New York | E36: 46335 | F36: 46337 | G36: Nov 9-11, 2026 | H36: New York City; venues NOT VERIFIED | I36: Middle-market M&A / PE / banking | J36: S44 | K36: Partial | M36: =IF(E36="","Check dates",IF(ReadMe!$B$4<E36,"Upcoming",IF(ReadMe!$B$4<=IF(F36="",E36,F36),"In progress / today","Past"))) -> Upcoming | N36: =IF(E36="","",E36-ReadMe!$B$4) -> 20 | O36: =IFERROR(INDEX(SourceMap!$C$2:$C$73,MATCH(LEFT(J36,FIND(",",J36&",")-1),SourceMap!$A$2:$A$73,0)),"") -> https://www.acg.org/nyc/events/acg-ny-2026-middle-market-week
A37: 36 | B37: B. Bank-hosted & sector investor conf. | C37: Stifel Healthcare Conference (NYC) | D37: Stifel | E37: 46336 | F37: 46338 | G37: Nov 10-12, 2026 | H37: New York; venue NOT VERIFIED; in person, client-only | I37: Healthcare | J37: S34 | K37: Confirmed | M37: =IF(E37="","Check dates",IF(ReadMe!$B$4<E37,"Upcoming",IF(ReadMe!$B$4<=IF(F37="",E37,F37),"In progress / today","Past"))) -> Upcoming | N37: =IF(E37="","",E37-ReadMe!$B$4) -> 21 | O37: =IFERROR(INDEX(SourceMap!$C$2:$C$73,MATCH(LEFT(J37,FIND(",",J37&",")-1),SourceMap!$A$2:$A$73,0)),"") -> https://www.cellectis.com/en/event/stifel-nyc-healthcare-conference/ | https://investors.oculis.com/events/event-details/stifel-healthcare-conference
A38: 37 | B38: C. Adjacent (dealmaking, family office, PE/credit) | C38: Family Office Forum Zurich (13th) | D38: Prestel & Partner | E38: 46336 | F38: 46337 | G38: Nov 10-11, 2026 | H38: Dolder Grand Hotel, Zurich | I38: Single family offices / UHNWIs | J38: S48 | K38: Confirmed | L38: Invitation-only. | M38: =IF(E38="","Check dates",IF(ReadMe!$B$4<E38,"Upcoming",IF(ReadMe!$B$4<=IF(F38="",E38,F38),"In progress / today","Past"))) -> Upcoming | N38: =IF(E38="","",E38-ReadMe!$B$4) -> 21 | O38: =IFERROR(INDEX(SourceMap!$C$2:$C$73,MATCH(LEFT(J38,FIND(",",J38&",")-1),SourceMap!$A$2:$A$73,0)),"") -> https://prestelandpartner.com/familyofficeforumzurich.html
A39: 38 | B39: C. Adjacent (dealmaking, family office, PE/credit) | C39: USA Family Office Conference (GFOC) | D39: Full name NOT VERIFIED | E39: 46338 | F39: 46338 | G39: Nov 12, 2026 | H39: Beverly Hills, CA; venue NOT VERIFIED | I39: Family-office peer exchange | J39: S49 | K39: Partial | M39: =IF(E39="","Check dates",IF(ReadMe!$B$4<E39,"Upcoming",IF(ReadMe!$B$4<=IF(F39="",E39,F39),"In progress / today","Past"))) -> Upcoming | N39: =IF(E39="","",E39-ReadMe!$B$4) -> 23 | O39: =IFERROR(INDEX(SourceMap!$C$2:$C$73,MATCH(LEFT(J39,FIND(",",J39&",")-1),SourceMap!$A$2:$A$73,0)),"") -> https://www.usafamilyofficeconference.com/
A40: 39 | B40: B. Bank-hosted & sector investor conf. | C40: Jefferies Global Healthcare Conference (London) | D40: Jefferies | E40: 46342 | G40: Starts Nov 16, 2026; end Nov 19 or Nov 20 | H40: London; venue NOT VERIFIED; invitation-only | I40: Healthcare / biotech | J40: S35 | K40: Partial | L40: DISCREPANCY on end date; one summary mixed in a 2025 date. Jefferies' page not read. | M40: =IF(E40="","Check dates",IF(ReadMe!$B$4<E40,"Upcoming",IF(ReadMe!$B$4<=IF(F40="",E40,F40),"In progress / today","Past"))) -> Upcoming | N40: =IF(E40="","",E40-ReadMe!$B$4) -> 27 | O40: =IFERROR(INDEX(SourceMap!$C$2:$C$73,MATCH(LEFT(J40,FIND(",",J40&",")-1),SourceMap!$A$2:$A$73,0)),"") -> https://www.jefferies.com/events/global-healthcare-conference-in-london-2/ | https://www.thepharmaletter.com/jefferies-london-healthcare-conference
...

Sheet Summary
A1: Summary (all figures are formulas over the Conferences sheet)
A2: As-of date: | B2: =ReadMe!B4 -> 46315
A4: By tier and confidence
A5: Tier | B5: Confirmed | C5: Partial | D5: Total
A6: A. Micro/small-cap & capital raising | B6: =COUNTIFS(Conferences!$B$2:$B$61,$A6,Conferences!$K$2:$K$61,"Confirmed") -> 11 | C6: =COUNTIFS(Conferences!$B$2:$B$61,$A6,Conferences!$K$2:$K$61,"Partial") -> 6 | D6: =SUM(B6:C6) -> 17
A7: B. Bank-hosted & sector investor conf. | B7: =COUNTIFS(Conferences!$B$2:$B$61,$A7,Conferences!$K$2:$K$61,"Confirmed") -> 10 | C7: =COUNTIFS(Conferences!$B$2:$B$61,$A7,Conferences!$K$2:$K$61,"Partial") -> 10 | D7: =SUM(B7:C7) -> 20
A8: C. Adjacent (dealmaking, family office, PE/credit) | B8: =COUNTIFS(Conferences!$B$2:$B$61,$A8,Conferences!$K$2:$K$61,"Confirmed") -> 15 | C8: =COUNTIFS(Conferences!$B$2:$B$61,$A8,Conferences!$K$2:$K$61,"Partial") -> 8 | D8: =SUM(B8:C8) -> 23
A9: Total | B9: =SUM(B6:B8) -> 36 | C9: =SUM(C6:C8) -> 24 | D9: =SUM(D6:D8) -> 60
A11: By status as of the as-of date
A12: Status | B12: Events
A13: Past | B13: =COUNTIF(Conferences!$M$2:$M$61,A13) -> 15
A14: In progress / today | B14: =COUNTIF(Conferences!$M$2:$M$61,A14) -> 2
A15: Upcoming | B15: =COUNTIF(Conferences!$M$2:$M$61,A15) -> 39
A16: Check dates | B16: =COUNTIF(Conferences!$M$2:$M$61,A16) -> 4
A17: Total | B17: =SUM(B13:B16) -> 60
A18: Check: equals total above | B18: =IF(B17=D9,"OK","MISMATCH") -> OK
A20: By start month (exact start dates only)
A21: Month | B21: Events starting
A22: Sep 2026 | B22: =COUNTIFS(Conferences!$E$2:$E$61,">="&DATE(2026,9,1),Conferences!$E$2:$E$61,"<"&DATE(2026,10,1)) -> 5
A23: Oct 2026 | B23: =COUNTIFS(Conferences!$E$2:$E$61,">="&DATE(2026,10,1),Conferences!$E$2:$E$61,"<"&DATE(2026,11,1)) -> 18
A24: Nov 2026 | B24: =COUNTIFS(Conferences!$E$2:$E$61,">="&DATE(2026,11,1),Conferences!$E$2:$E$61,"<"&DATE(2026,12,1)) -> 22
A25: Dec 2026 | B25: =COUNTIFS(Conferences!$E$2:$E$61,">="&DATE(2026,12,1),Conferences!$E$2:$E$61,"<"&DATE(2027,1,1)) -> 11
A26: No exact start date | B26: =D9-SUM(B22:B25) -> 4
A27: Note: 'No exact start date' = conflicted, month-only, or multi-date rows (shown as 'Check dates' in Status).
A29: Leads on the Leads sheet (unverified, not counted above) | B29: =COUNTA(Leads!A2:A200) -> 15

Sheet Leads
A1: Item (UNVERIFIED, do not rely on dates) | B1: What was and was not found | C1: Src IDs
A2: Northland Growth Conference (December) | B2: Source says 'Tuesday, December 16, 2026' but Dec 16, 2026 is a Wednesday (Dec 16, 2025 was a Tuesday). Likely a prior-year date. Do not rely. | C2: S39
A3: Benzinga Healthcare Small Cap Conference | B3: Page title 'Sept 29 - 30'; year not shown, format unverified. | C3: S61
A4: Craig-Hallum 17th Annual Alpha Select Conference | B4: Page exists; a summary hinted Nov 17, 2026 but nothing retrieved supports it. The 2025 edition was Nov 18, 2025. | C4: S63
A5: Craig-Hallum other events (Institutional Investor Conference; Biotech Catalyst, Houston, '11/3') | B5: No year or dates retrieved. | C5: S63
A6: MicroCap Rodeo Fall Conference | B6: Headline 'Oct 16th in NYC', year not visible; may be a prior year or the same as The Small Cap Showcase. | C6: S65
A7: Investor Summit Group Q4 Virtual Investor Summit | B7: No Q4 2026 date found (Q1-Q3 2026 dates only). | C7: S66
A8: Benchmark 15th Annual Discovery One-on-One Investor Conference | B8: No 2026 date; past editions were early December in NYC (not used to infer 2026). | C8: S71
A9: Evercore ISI 9th HealthCONx | B9: Aggregator says date/place 'yet to be confirmed'. | C9: S72
A10: SuperReturn Private Credit North America; SuperReturn Europe (Amsterdam) | B10: Hinted Nov 3-6 / Nov 3 in summaries only; no source URL attributed. | C10: S60
A11: Opal ABS & Fintech Specialty Finance Forum | B11: 'December 2026' from URL title only. | C11: S56
A12: EMC2 Conference 2026 (Cornell Tech, NYC, Nov 6) | B12: Search summary only; no URL, organizer or focus. | C12: -
... A16: MeetMax event_145007 (your first example) | B16: NOT IDENTIFIED. meetmax.com is blocked and searches for the ID returned nothing. IDs found for reference: Lytham Fall 2024 = 111653; Craig-Hallum May 2024 = 103561. The ID likely dates from 2026 (inference only, not a retrieved fact). | C16: S69

Sheet SourceMap
A1: ID | B1: Source | C1: URL(s) | D1: Retrieved
A2: S1 | B2: Comstock release (Lytham Fall 2026), GlobeNewswire 2026-09-28 | C2: https://www.globenewswire.com/news-release/2026/09/28/3369705/0/en/comstock-to-participate-in-the-lytham-partners-fall-2026-investor-conference.html | D2: 46293
A3: S2 | B3: LiqTech release (Lytham Fall 2026), GlobeNewswire 2026-09-17 | C3: https://www.globenewswire.com/news-release/2026/09/17/3364386/0/en/liqtech-to-participate-in-the-lytham-partners-fall-2026-investor-conference.html | D3: 46293
A4: S3 | B4: Smallcap Discoveries event page | C4: https://smallcapdiscoveries.com/annual-smallcap-discoveries-conference-2026/ | D4: 46293
A5: S4 | B5: Avante release (Smallcap Discoveries), Nasdaq 2026-09-22 | C5: https://www.nasdaq.com/press-release/avante-present-annual-smallcap-discoveries-conference-vancouver-2026-09-22 | D5: 46293
A6: S5 | B6: ROTH Healthcare Opportunities release, GlobeNewswire 2026-09-22 | C6: https://www.globenewswire.com/news-release/2026/09/22/3366425/0/en/roth-to-host-5th-annual-healthcare-opportunities-conference-on-september-29-in-new-york-city.html | D6: 46293
A7: S6 | B7: InvestorWire: ROTH investor events through June 2027 | C7: https://www.investorwire.com/investor-news-breaks/investornewsbreaks-roth-capital-partners-hosts-and-sponsors-investor-events-through-june-2027/ | D7: 46293
A8: S7 | B8: The Small Cap Showcase site | C8: https://www.smallcapshowcase.com/ | D8: 46293
A9: S8 | B9: AI & Tech Virtual Investor Conference agenda release, GlobeNewswire 2026-09-28 | C9: https://www.globenewswire.com/news-release/2026/09/28/3369959/0/en/ai-tech-virtual-investor-conference-agenda-announced.html | D9: 46293
A10: S9 | B10: NewMediaWire: Oct 1 Virtual Investor Conference | C10: https://www.newmediawire.com/news/ai-tech-companies-present-live-and-take-investor-meetings-at-the-october-1-virtual-investor-conference-7090116 | D10: 46293
A11: S10 | B11: Noble Oct 2026 virtual conference page | C11: https://nobleconference.com/virtual-october-2026/ | D11: 46293
A12: S11 | B12: CBAK Energy release (Noble Oct), GlobeNewswire 2026-09-16 | C12: https://www.globenewswire.com/news-release/2026/09/16/3363231/0/en/cbak-energy-to-present-at-noble-capital-markets-emerging-growth-virtual-equity-conference-on-october-1-2026.html | D12: 46293
A13: S12 | B13: NIBA Oct 6-7, 2026 conference page | C13: https://nibanet.org/conference/niba-october-6-7-2026-ft-lauderdale-fl-conference/ | D13: 46293
... A73: S72 | B73: Evercore ISI HealthCONx (aggregator listing) | C73: https://www.life-sciences-france.com/product/evercore-isi-healthconx-conference-group-investment-investor-financing-2001-32757.html | D73: 46293

Sheet Audit
A1: Type | B1: Issue | C1: Detail
A2: Audit | B2: Data is older than the as-of date. | C2: Built from research retrieved 2026-09-28; the as-of date is later. Events on or before the as-of date show 'Past' by calculation only. Upcoming events and any events announced since retrieval were not re-checked when this workbook was built.
A3: Audit | B3: Formulas not run through a spreadsheet engine here. | C3: LibreOffice would not open any file in this build environment, so the skill's recalculation step could not run. Cached values stored in the file were computed separately in Python and cross-checked; Excel recalculates when you open the file. If a Status or Summary cell looks wrong after opening, tell me.
A4: Audit | B4: No page was opened. | C4: Every date in this document comes from search-result text (page titles, AI-written summaries of pages) or press-release text. All four of your example sites were blocked by the network proxy. Search summaries can be wrong, so 'Confirmed' means only 'dates and location are stated in at least one retrieved source', not 'verified on the organizer's site'. Before you ship, open each organizer page for the events you will act on.
A5: Audit | B5: Search coverage is incomplete. | C5: See coverage gaps. The absence of an event here means 'not found', never 'does not exist'. In particular, the large bank-hosted institutional conferences are under-covered.
A6: Audit | B6: Northland date rejected. | C6: Weekday cross-check failed: Dec 16, 2026 is a Wednesday, but the source said Tuesday. Moved to unverified leads.
A7: Audit | B7: Two agents' confidence downgraded. | C7: Piper Sandler (aggregator only) and Wolfe (single issuer site) were reported as Confirmed; shown here as Partial.
A8: Audit | B8: Conflicts unresolved. | C8: Maxim end date/scope; ThinkEquity venue; Jefferies London end date; SuperReturn Middle East dates; Mining & Critical Minerals Canada dates; Capital Link Oct 20 forum; Sidoti December end date; PIPEs stale AllEvents listing (Nov 13-14).
A9: Audit | B9: Year inferences. | C9: Small Cap Showcase's year is inferred from weekday and registration text (Oct 1, 2026 is a Thursday). Several other single-source rows rely on one snippet.
A10: Audit | B10: ROTH Nov/Dec rows. | C10: Event names come from InvestorWire's title; dates were matched to the B2i calendar by date only. Treat as leads until the ROTH page is read.
A11: Audit | B11: Organizer claims are not independently checked. | C11: Attendance and company counts (e.g. NIBA '350+ investment professionals') are the organizers' own statements, relayed by search summaries.
A12: Audit | B12: Scope assumption. | C12: You gave four examples, not a definition. I read them as micro/small-cap investor, PIPE and capital-markets conferences, and added bank-hosted sector conferences and adjacent dealmaking/private-markets events as separate tiers. If you meant a different category, the scoping should change.
A13: Audit | B13: Calculated figures. | C13: Counts below are simple tallies of rows in this document. Weekday checks were computed with Python's calendar (datetime).
A14: Coverage gap | C14: Not searched (WebSearch budget of 200 calls ran out in each research thread): KeyBanc, TD Cowen, William Blair, Susquehanna, Loop, Barclays, Wells Fargo, Deutsche Bank, BMO, RBC, Goldman Sachs, Raymond James, Canaccord fall events, BTIG, Chardan, Truist, Cantor fall events, H.C. Wainwright, Oppenheimer fall, Needham fall, Morgan Stanley and Citi/UBS December events, Capital Link investor events beyond the forums shown, Wall Street Reporter, Crescendo, KCSA, MZ Group, Alliance Advisors, TWST, Investor Brand Network, RedChip, Sequire, Proactive, MicroCapClub events.
A15: Coverage gap | C15: Sectors with no dedicated search: crypto/digital assets, cannabis/psychedelics, oil and gas/energy (e.g. EnerCom), consumer/retail, fintech, and Asia beyond SuperReturn Asia.
A16: Coverage gap | C16: Searched, nothing found in window: Lytham Partners events after Sep 29-30; any MeetMax-branded Q4 event; Context Summits; a fall SPAC/IPO conference; DealFlow's other fall events; Cambridge House fall events; Denver Gold Forum (timing reported as September).
A17: Coverage gap | C17: Excluded as off-category: J.P. Morgan corporate investor conferences (Nov 17-20, London/Paris/New York; sell-side sector events) and EPC Mining Summit Toronto (Nov 3-4).
A18: Coverage gap | C18: Excluded as outside the window (examples): Sidoti Sep 23-24; Emerging Growth Conference 96 (Sep 23-24); iAccess Alpha Fall (Sep 15-16); H.C. Wainwright (Sep 14-16); NIBA 152nd (Mar 11-12, 2026); DealFlow Discovery (Jan 26-28, 2027); NobleCon22 (Feb 23-24, 2027).
